[2023-01-18T20:10:35.102+0000] {taskinstance.py:1087} INFO - Dependencies all met for <TaskInstance: Kafka_consumer.producer manual__2023-01-17T19:52:55.119227+00:00 [queued]>
[2023-01-18T20:10:35.112+0000] {taskinstance.py:1087} INFO - Dependencies all met for <TaskInstance: Kafka_consumer.producer manual__2023-01-17T19:52:55.119227+00:00 [queued]>
[2023-01-18T20:10:35.112+0000] {taskinstance.py:1283} INFO - 
--------------------------------------------------------------------------------
[2023-01-18T20:10:35.112+0000] {taskinstance.py:1284} INFO - Starting attempt 22 of 27
[2023-01-18T20:10:35.113+0000] {taskinstance.py:1285} INFO - 
--------------------------------------------------------------------------------
[2023-01-18T20:10:35.126+0000] {taskinstance.py:1304} INFO - Executing <Task(ProduceToTopicOperator): producer> on 2023-01-17 19:52:55.119227+00:00
[2023-01-18T20:10:35.131+0000] {standard_task_runner.py:55} INFO - Started process 340 to run task
[2023-01-18T20:10:35.133+0000] {standard_task_runner.py:82} INFO - Running: ['***', 'tasks', 'run', 'Kafka_consumer', 'producer', 'manual__2023-01-17T19:52:55.119227+00:00', '--job-id', '35', '--raw', '--subdir', 'DAGS_FOLDER/producer_dag.py', '--cfg-path', '/tmp/tmpeycujfd2']
[2023-01-18T20:10:35.134+0000] {standard_task_runner.py:83} INFO - Job 35: Subtask producer
[2023-01-18T20:10:35.186+0000] {task_command.py:389} INFO - Running <TaskInstance: Kafka_consumer.producer manual__2023-01-17T19:52:55.119227+00:00 [running]> on host 7a3ca62d008e
[2023-01-18T20:10:35.246+0000] {taskinstance.py:1513} INFO - Exporting the following env vars:
AIRFLOW_CTX_DAG_OWNER=***
AIRFLOW_CTX_DAG_ID=Kafka_consumer
AIRFLOW_CTX_TASK_ID=producer
AIRFLOW_CTX_EXECUTION_DATE=2023-01-17T19:52:55.119227+00:00
AIRFLOW_CTX_TRY_NUMBER=22
AIRFLOW_CTX_DAG_RUN_ID=manual__2023-01-17T19:52:55.119227+00:00
[2023-01-18T20:10:35.255+0000] {taskinstance.py:1772} ERROR - Task failed with exception
Traceback (most recent call last):
  File "/home/airflow/.local/lib/python3.7/site-packages/airflow_provider_kafka/operators/produce_to_topic.py", line 100, in execute
    kafka_conn_id=self.kafka_conn_id, config=self.kafka_config
  File "/home/airflow/.local/lib/python3.7/site-packages/airflow_provider_kafka/hooks/producer.py", line 28, in __init__
    "One of config['bootstrap.servers'] or kafka_conn_id must be provided."
airflow.exceptions.AirflowException: One of config['bootstrap.servers'] or kafka_conn_id must be provided.
[2023-01-18T20:10:35.258+0000] {taskinstance.py:1327} INFO - Marking task as UP_FOR_RETRY. dag_id=Kafka_consumer, task_id=producer, execution_date=20230117T195255, start_date=20230118T201035, end_date=20230118T201035
[2023-01-18T20:10:35.269+0000] {standard_task_runner.py:105} ERROR - Failed to execute job 35 for task producer (One of config['bootstrap.servers'] or kafka_conn_id must be provided.; 340)
[2023-01-18T20:10:35.305+0000] {local_task_job.py:159} INFO - Task exited with return code 1
[2023-01-18T20:10:35.323+0000] {taskinstance.py:2582} INFO - 0 downstream tasks scheduled from follow-on schedule check
